Workbook

Sheet 1 Ангар Склад 2 въезд
A1: День нед | B1: Дата | C1: Время | D1: Событие | E1: Объект | F1: Груз | G1: Кол-во | H1: Примечание | I1: Name | J1: Folder Path | K1: RelativePath | L1: Подпись | M1: Ссылка на фото | N1: Камера
A2: пн | B2: 45971 | C2: 0.49480324 | D2: Выезд с территории | E2: Погрузчик базы | F2: порожний | I2: E33149364_6_20251110T115231Z.jpg | J2: C:\ВИДЕОНАБЛЮДЕНИЕ\1 Ангар Склад 2 въезд\ | K2: 1 Ангар Склад 2 въезд\E33149364_6_20251110T115231Z.jpg | L2: пн 10.11.2025 — 11:52:31 | M2: =HYPERLINK(склад2въезд[[#This Row],[RelativePath]]) -> 1 Ангар Склад 2 въезд\E33149364_6_20251110T115231Z.jpg | N2: =VLOOKUP(склад2въезд[[#This Row],[Name]], СпрСобытий!$F:$G, 2, FALSE) -> Ангар Склад 2 въезд
A3: пн | B3: 45971 | C3: 0.50054398 | D3: Въезд на базу | E3: Легковой с прицепом | F3: порожний | I3: E33149364_6_20251110T120047Z.jpg | J3: C:\ВИДЕОНАБЛЮДЕНИЕ\1 Ангар Склад 2 въезд\ | K3: 1 Ангар Склад 2 въезд\E33149364_6_20251110T120047Z.jpg | L3: пн 10.11.2025 — 12:00:47 | M3: =HYPERLINK(склад2въезд[[#This Row],[RelativePath]]) -> 1 Ангар Склад 2 въезд\E33149364_6_20251110T120047Z.jpg | N3: =VLOOKUP(склад2въезд[[#This Row],[Name]], СпрСобытий!$F:$G, 2, FALSE) -> Ангар Склад 2 въезд
A4: пн | B4: 45971 | C4: 0.50060185 | D4: Въезд на базу | E4: Легковой с прицепом | F4: порожний | I4: E33149364_6_20251110T120052Z.jpg | J4: C:\ВИДЕОНАБЛЮДЕНИЕ\1 Ангар Склад 2 въезд\ | K4: 1 Ангар Склад 2 въезд\E33149364_6_20251110T120052Z.jpg | L4: пн 10.11.2025 — 12:00:52 | M4: =HYPERLINK(склад2въезд[[#This Row],[RelativePath]]) -> 1 Ангар Склад 2 въезд\E33149364_6_20251110T120052Z.jpg | N4: =VLOOKUP(склад2въезд[[#This Row],[Name]], СпрСобытий!$F:$G, 2, FALSE) -> Ангар Склад 2 въезд
A5: пн | B5: 45971 | C5: 0.51984954 | D5: Выезд с территории | E5: Легковой с прицепом | F5: мешки с опилками | G5: 3 | I5: E33149364_6_20251110T122835Z.jpg | J5: C:\ВИДЕОНАБЛЮДЕНИЕ\1 Ангар Склад 2 въезд\ | K5: 1 Ангар Склад 2 въезд\E33149364_6_20251110T122835Z.jpg | L5: пн 10.11.2025 — 12:28:35 | M5: =HYPERLINK(склад2въезд[[#This Row],[RelativePath]]) -> 1 Ангар Склад 2 въезд\E33149364_6_20251110T122835Z.jpg | N5: =VLOOKUP(склад2въезд[[#This Row],[Name]], СпрСобытий!$F:$G, 2, FALSE) -> Ангар Склад 2 въезд
A6: пн | B6: 45971 | C6: 0.56978009 | D6: Въезд на базу | E6: Погрузчик базы | F6: доски | I6: E33149364_6_20251110T134029Z.jpg | J6: C:\ВИДЕОНАБЛЮДЕНИЕ\1 Ангар Склад 2 въезд\ | K6: 1 Ангар Склад 2 въезд\E33149364_6_20251110T134029Z.jpg | L6: пн 10.11.2025 — 13:40:29 | M6: =HYPERLINK(склад2въезд[[#This Row],[RelativePath]]) -> 1 Ангар Склад 2 въезд\E33149364_6_20251110T134029Z.jpg | N6: =VLOOKUP(склад2въезд[[#This Row],[Name]], СпрСобытий!$F:$G, 2, FALSE) -> Ангар Склад 2 въезд
A7: пн | B7: 45971 | C7: 0.57337963 | D7: Выезд с территории | E7: Погрузчик базы | F7: доски | H7: груз один и тот же | I7: E33149364_6_20251110T134540Z.jpg | J7: C:\ВИДЕОНАБЛЮДЕНИЕ\1 Ангар Склад 2 въезд\ | K7: 1 Ангар Склад 2 въезд\E33149364_6_20251110T134540Z.jpg | L7: пн 10.11.2025 — 13:45:40 | M7: =HYPERLINK(склад2въезд[[#This Row],[RelativePath]]) -> 1 Ангар Склад 2 въезд\E33149364_6_20251110T134540Z.jpg | N7: =VLOOKUP(склад2въезд[[#This Row],[Name]], СпрСобытий!$F:$G, 2, FALSE) -> Ангар Склад 2 въезд
A8: пн | B8: 45971 | C8: 0.60597222 | D8: Въезд на базу | E8: Погрузчик базы | F8: доски | H8: груз один и тот же | I8: E33149364_6_20251110T143236Z.jpg | J8: C:\ВИДЕОНАБЛЮДЕНИЕ\1 Ангар Склад 2 въезд\ | K8: 1 Ангар Склад 2 въезд\E33149364_6_20251110T143236Z.jpg | L8: пн 10.11.2025 — 14:32:36 | M8: =HYPERLINK(склад2въезд[[#This Row],[RelativePath]]) -> 1 Ангар Склад 2 въезд\E33149364_6_20251110T143236Z.jpg | N8: =VLOOKUP(склад2въезд[[#This Row],[Name]], СпрСобытий!$F:$G, 2, FALSE) -> Ангар Склад 2 въезд
A9: вт | B9: 45972 | C9: 0.39128472 | D9: Въезд на базу | E9: Погрузчик, желтый | F9: порожний | I9: E33149364_6_20251111T092327Z.jpg | J9: C:\ВИДЕОНАБЛЮДЕНИЕ\1 Ангар Склад 2 въезд\ | K9: 1 Ангар Склад 2 въезд\E33149364_6_20251111T092327Z.jpg | L9: вт 11.11.2025 — 09:23:27 | M9: =HYPERLINK(склад2въезд[[#This Row],[RelativePath]]) -> 1 Ангар Склад 2 въезд\E33149364_6_20251111T092327Z.jpg | N9: =VLOOKUP(склад2въезд[[#This Row],[Name]], СпрСобытий!$F:$G, 2, FALSE) -> Ангар Склад 2 въезд
A10: вт | B10: 45972 | C10: 0.44765046 | D10: Выезд с территории | E10: Погрузчик, желтый | F10: бревна со сруба | I10: E33149364_6_20251111T104437Z.jpg | J10: C:\ВИДЕОНАБЛЮДЕНИЕ\1 Ангар Склад 2 въезд\ | K10: 1 Ангар Склад 2 въезд\E33149364_6_20251111T104437Z.jpg | L10: вт 11.11.2025 — 10:44:37 | M10: =HYPERLINK(склад2въезд[[#This Row],[RelativePath]]) -> 1 Ангар Склад 2 въезд\E33149364_6_20251111T104437Z.jpg | N10: =VLOOKUP(склад2въезд[[#This Row],[Name]], СпрСобытий!$F:$G, 2, FALSE) -> Ангар Склад 2 въезд
A11: вт | B11: 45972 | C11: 0.44944444 | D11: Въезд на базу | E11: Газель бортовая, синяя кабина | F11: порожний | I11: E33149364_6_20251111T104712Z.jpg | J11: C:\ВИДЕОНАБЛЮДЕНИЕ\1 Ангар Склад 2 въезд\ | K11: 1 Ангар Склад 2 въезд\E33149364_6_20251111T104712Z.jpg | L11: вт 11.11.2025 — 10:47:12 | M11: =HYPERLINK(склад2въезд[[#This Row],[RelativePath]]) -> 1 Ангар Склад 2 въезд\E33149364_6_20251111T104712Z.jpg | N11: =VLOOKUP(склад2въезд[[#This Row],[Name]], СпрСобытий!$F:$G, 2, FALSE) -> Ангар Склад 2 въезд
A12: вт | B12: 45972 | C12: 0.45118056 | D12: Задний ход, въезд на территорию | E12: Газель бортовая, синяя кабина | F12: порожний | I12: E33149364_6_20251111T104942Z.jpg | J12: C:\ВИДЕОНАБЛЮДЕНИЕ\1 Ангар Склад 2 въезд\ | K12: 1 Ангар Склад 2 въезд\E33149364_6_20251111T104942Z.jpg | L12: вт 11.11.2025 — 10:49:42 | M12: =HYPERLINK(склад2въезд[[#This Row],[RelativePath]]) -> 1 Ангар Склад 2 въезд\E33149364_6_20251111T104942Z.jpg | N12: =VLOOKUP(склад2въезд[[#This Row],[Name]], СпрСобытий!$F:$G, 2, FALSE) -> Ангар Склад 2 въезд
A13: вт | B13: 45972 | C13: 0.45136574 | D13: Въезд на второстепенную дорогу | E13: Газель бортовая, синяя кабина | F13: порожний | I13: E33149364_6_20251111T104958Z.jpg | J13: C:\ВИДЕОНАБЛЮДЕНИЕ\1 Ангар Склад 2 въезд\ | K13: 1 Ангар Склад 2 въезд\E33149364_6_20251111T104958Z.jpg | L13: вт 11.11.2025 — 10:49:58 | M13: =HYPERLINK(склад2въезд[[#This Row],[RelativePath]]) -> 1 Ангар Склад 2 въезд\E33149364_6_20251111T104958Z.jpg | N13: =VLOOKUP(склад2въезд[[#This Row],[Name]], СпрСобытий!$F:$G, 2, FALSE) -> Ангар Склад 2 въезд
A14: вт | B14: 45972 | C14: 0.48476852 | D14: Выезд с территории | E14: Газель бортовая, синяя кабина | F14: доски | I14: E33149364_6_20251111T113804Z.jpg | J14: C:\ВИДЕОНАБЛЮДЕНИЕ\1 Ангар Склад 2 въезд\ | K14: 1 Ангар Склад 2 въезд\E33149364_6_20251111T113804Z.jpg | L14: вт 11.11.2025 — 11:38:04 | M14: =HYPERLINK(склад2въезд[[#This Row],[RelativePath]]) -> 1 Ангар Склад 2 въезд\E33149364_6_20251111T113804Z.jpg | N14: =VLOOKUP(склад2въезд[[#This Row],[Name]], СпрСобытий!$F:$G, 2, FALSE) -> Ангар Склад 2 въезд
A15: вт | B15: 45972 | C15: 0.53641204 | D15: Выезд с территории | E15: Погрузчик базы | F15: красные доски, тюки | I15: E33149364_6_20251111T125226Z.jpg | J15: C:\ВИДЕОНАБЛЮДЕНИЕ\1 Ангар Склад 2 въезд\ | K15: 1 Ангар Склад 2 въезд\E33149364_6_20251111T125226Z.jpg | L15: вт 11.11.2025 — 12:52:26 | M15: =HYPERLINK(склад2въезд[[#This Row],[RelativePath]]) -> 1 Ангар Склад 2 въезд\E33149364_6_20251111T125226Z.jpg | N15: =VLOOKUP(склад2въезд[[#This Row],[Name]], СпрСобытий!$F:$G, 2, FALSE) -> Ангар Склад 2 въезд
A16: вт | B16: 45972 | C16: 0.65542824 | D16: Въезд на базу | E16: Погрузчик базы | F16: порожний | I16: E33149364_6_20251111T154349Z.jpg | J16: C:\ВИДЕОНАБЛЮДЕНИЕ\1 Ангар Склад 2 въезд\ | K16: 1 Ангар Склад 2 въезд\E33149364_6_20251111T154349Z.jpg | L16: вт 11.11.2025 — 15:43:49 | M16: =HYPERLINK(склад2въезд[[#This Row],[RelativePath]]) -> 1 Ангар Склад 2 въезд\E33149364_6_20251111T154349Z.jpg | N16: =VLOOKUP(склад2въезд[[#This Row],[Name]], СпрСобытий!$F:$G, 2, FALSE) -> Ангар Склад 2 въезд
A17: ср | B17: 45973 | C17: 0.6768287 | D17: Въезд на базу | E17: Самосвал красный | F17: не видно, что находится в кузове | I17: E33149364_6_20251112T161438Z.jpg | J17: C:\ВИДЕОНАБЛЮДЕНИЕ\1 Ангар Склад 2 въезд\ | K17: 1 Ангар Склад 2 въезд\E33149364_6_20251112T161438Z.jpg | L17: ср 12.11.2025 — 16:14:38 | M17: =HYPERLINK(склад2въезд[[#This Row],[RelativePath]]) -> 1 Ангар Склад 2 въезд\E33149364_6_20251112T161438Z.jpg | N17: =VLOOKUP(склад2въезд[[#This Row],[Name]], СпрСобытий!$F:$G, 2, FALSE) -> Ангар Склад 2 въезд
A18: ср | B18: 45973 | C18: 0.71020833 | D18: Выезд с территории | E18: Самосвал красный | F18: земля | I18: E33149364_6_20251112T170242Z.jpg | J18: C:\ВИДЕОНАБЛЮДЕНИЕ\1 Ангар Склад 2 въезд\ | K18: 1 Ангар Склад 2 въезд\E33149364_6_20251112T170242Z.jpg | L18: ср 12.11.2025 — 17:02:42 | M18: =HYPERLINK(склад2въезд[[#This Row],[RelativePath]]) -> 1 Ангар Склад 2 въезд\E33149364_6_20251112T170242Z.jpg | N18: =VLOOKUP(склад2въезд[[#This Row],[Name]], СпрСобытий!$F:$G, 2, FALSE) -> Ангар Склад 2 въезд
A19: чт | B19: 45974 | C19: 0.36740741 | D19: Выезд с территории | E19: Погрузчик базы | F19: порожний | I19: E33149364_6_20251113T084904Z.jpg | J19: C:\ВИДЕОНАБЛЮДЕНИЕ\1 Ангар Склад 2 въезд\ | K19: 1 Ангар Склад 2 въезд\E33149364_6_20251113T084904Z.jpg | L19: чт 13.11.2025 — 08:49:04 | M19: =HYPERLINK(склад2въезд[[#This Row],[RelativePath]]) -> 1 Ангар Склад 2 въезд\E33149364_6_20251113T084904Z.jpg | N19: =VLOOKUP(склад2въезд[[#This Row],[Name]], СпрСобытий!$F:$G, 2, FALSE) -> Ангар Склад 2 въезд
A20: чт | B20: 45974 | C20: 0.37163194 | D20: Въезд на базу | E20: Газель базы | F20: порожний | I20: E33149364_6_20251113T085509Z.jpg | J20: C:\ВИДЕОНАБЛЮДЕНИЕ\1 Ангар Склад 2 въезд\ | K20: 1 Ангар Склад 2 въезд\E33149364_6_20251113T085509Z.jpg | L20: чт 13.11.2025 — 08:55:09 | M20: =HYPERLINK(склад2въезд[[#This Row],[RelativePath]]) -> 1 Ангар Склад 2 въезд\E33149364_6_20251113T085509Z.jpg | N20: =VLOOKUP(склад2въезд[[#This Row],[Name]], СпрСобытий!$F:$G, 2, FALSE) -> Ангар Склад 2 въезд
... A27: пт | B27: 45975 | C27: 0.53131944 | D27: Выезд со второстепенной дороги | E27: Трактор базы | F27: порожний | I27: E33149364_6_20251114T124506Z.jpg | J27: C:\ВИДЕОНАБЛЮДЕНИЕ\1 Ангар Склад 2 въезд\ | K27: 1 Ангар Склад 2 въезд\E33149364_6_20251114T124506Z.jpg | L27: пт 14.11.2025 — 12:45:06 | M27: =HYPERLINK(склад2въезд[[#This Row],[RelativePath]]) -> 1 Ангар Склад 2 въезд\E33149364_6_20251114T124506Z.jpg | N27: =VLOOKUP(склад2въезд[[#This Row],[Name]], СпрСобытий!$F:$G, 2, FALSE) -> Ангар Склад 2 въезд
A28: пт | B28: 45975 | C28: 0.53512731 | D28: Въезд на базу | E28: Трактор базы | F28: шина | G28: 1 | I28: E33149364_6_20251114T125035Z.jpg | J28: C:\ВИДЕОНАБЛЮДЕНИЕ\1 Ангар Склад 2 въезд\ | K28: 1 Ангар Склад 2 въезд\E33149364_6_20251114T125035Z.jpg | L28: пт 14.11.2025 — 12:50:35 | M28: =HYPERLINK(склад2въезд[[#This Row],[RelativePath]]) -> 1 Ангар Склад 2 въезд\E33149364_6_20251114T125035Z.jpg | N28: =VLOOKUP(склад2въезд[[#This Row],[Name]], СпрСобытий!$F:$G, 2, FALSE) -> Ангар Склад 2 въезд
A29: пт | B29: 45975 | C29: 0.53766204 | D29: Выезд с территории | E29: Трактор базы | F29: порожний | I29: E33149364_6_20251114T125414Z.jpg | J29: C:\ВИДЕОНАБЛЮДЕНИЕ\1 Ангар Склад 2 въезд\ | K29: 1 Ангар Склад 2 въезд\E33149364_6_20251114T125414Z.jpg | L29: пт 14.11.2025 — 12:54:14 | M29: =HYPERLINK(склад2въезд[[#This Row],[RelativePath]]) -> 1 Ангар Склад 2 въезд\E33149364_6_20251114T125414Z.jpg | N29: =VLOOKUP(склад2въезд[[#This Row],[Name]], СпрСобытий!$F:$G, 2, FALSE) -> Ангар Склад 2 въезд
A30: пт | B30: 45975 | C30: 0.53960648 | D30: Задний ход, въезд на территорию | E30: Самосвал красный | F30: щебень | G30: 1 | I30: E33149364_6_20251114T125702Z.jpg | J30: C:\ВИДЕОНАБЛЮДЕНИЕ\1 Ангар Склад 2 въезд\ | K30: 1 Ангар Склад 2 въезд\E33149364_6_20251114T125702Z.jpg | L30: пт 14.11.2025 — 12:57:02 | M30: =HYPERLINK(склад2въезд[[#This Row],[RelativePath]]) -> 1 Ангар Склад 2 въезд\E33149364_6_20251114T125702Z.jpg | N30: =VLOOKUP(склад2въезд[[#This Row],[Name]], СпрСобытий!$F:$G, 2, FALSE) -> Ангар Склад 2 въезд
A31: пт | B31: 45975 | C31: 0.54020833 | D31: Въезд на второстепенную дорогу | E31: Трактор базы | F31: шина | G31: 1 | I31: E33149364_6_20251114T125754Z.jpg | J31: C:\ВИДЕОНАБЛЮДЕНИЕ\1 Ангар Склад 2 въезд\ | K31: 1 Ангар Склад 2 въезд\E33149364_6_20251114T125754Z.jpg | L31: пт 14.11.2025 — 12:57:54 | M31: =HYPERLINK(склад2въезд[[#This Row],[RelativePath]]) -> 1 Ангар Склад 2 въезд\E33149364_6_20251114T125754Z.jpg | N31: =VLOOKUP(склад2въезд[[#This Row],[Name]], СпрСобытий!$F:$G, 2, FALSE) -> Ангар Склад 2 въезд
A32: пт | B32: 45975 | C32: 0.54204861 | D32: Выезд с территории | E32: Самосвал красный | F32: порожний | I32: E33149364_6_20251114T130033Z.jpg | J32: C:\ВИДЕОНАБЛЮДЕНИЕ\1 Ангар Склад 2 въезд\ | K32: 1 Ангар Склад 2 въезд\E33149364_6_20251114T130033Z.jpg | L32: пт 14.11.2025 — 13:00:33 | M32: =HYPERLINK(склад2въезд[[#This Row],[RelativePath]]) -> 1 Ангар Склад 2 въезд\E33149364_6_20251114T130033Z.jpg | N32: =VLOOKUP(склад2въезд[[#This Row],[Name]], СпрСобытий!$F:$G, 2, FALSE) -> Ангар Склад 2 въезд
A33: пт | B33: 45975 | C33: 0.55090278 | D33: Задний ход, въезд на территорию | E33: Самосвал красный | F33: щебень | G33: 1 | I33: E33149364_6_20251114T131318Z.jpg | J33: C:\ВИДЕОНАБЛЮДЕНИЕ\1 Ангар Склад 2 въезд\ | K33: 1 Ангар Склад 2 въезд\E33149364_6_20251114T131318Z.jpg | L33: пт 14.11.2025 — 13:13:18 | M33: =HYPERLINK(склад2въезд[[#This Row],[RelativePath]]) -> 1 Ангар Склад 2 въезд\E33149364_6_20251114T131318Z.jpg | N33: =VLOOKUP(склад2въезд[[#This Row],[Name]], СпрСобытий!$F:$G, 2, FALSE) -> Ангар Склад 2 въезд
A34: пт | B34: 45975 | C34: 0.55299769 | D34: Выезд с территории | E34: Самосвал красный | F34: порожний | I34: E33149364_6_20251114T131619Z.jpg | J34: C:\ВИДЕОНАБЛЮДЕНИЕ\1 Ангар Склад 2 въезд\ | K34: 1 Ангар Склад 2 въезд\E33149364_6_20251114T131619Z.jpg | L34: пт 14.11.2025 — 13:16:19 | M34: =HYPERLINK(склад2въезд[[#This Row],[RelativePath]]) -> 1 Ангар Склад 2 въезд\E33149364_6_20251114T131619Z.jpg | N34: =VLOOKUP(склад2въезд[[#This Row],[Name]], СпрСобытий!$F:$G, 2, FALSE) -> Ангар Склад 2 въезд
A35: пт | B35: 45975 | C35: 0.56123843 | D35: Задний ход, въезд на территорию | E35: Самосвал красный | F35: щебень | G35: 1 | I35: E33149364_6_20251114T132811Z.jpg | J35: C:\ВИДЕОНАБЛЮДЕНИЕ\1 Ангар Склад 2 въезд\ | K35: 1 Ангар Склад 2 въезд\E33149364_6_20251114T132811Z.jpg | L35: пт 14.11.2025 — 13:28:11 | M35: =HYPERLINK(склад2въезд[[#This Row],[RelativePath]]) -> 1 Ангар Склад 2 въезд\E33149364_6_20251114T132811Z.jpg | N35: =VLOOKUP(склад2въезд[[#This Row],[Name]], СпрСобытий!$F:$G, 2, FALSE) -> Ангар Склад 2 въезд
A36: пт | B36: 45975 | C36: 0.56293981 | D36: Выезд с территории | E36: Самосвал красный | F36: порожний | I36: E33149364_6_20251114T133038Z.jpg | J36: C:\ВИДЕОНАБЛЮДЕНИЕ\1 Ангар Склад 2 въезд\ | K36: 1 Ангар Склад 2 въезд\E33149364_6_20251114T133038Z.jpg | L36: пт 14.11.2025 — 13:30:38 | M36: =HYPERLINK(склад2въезд[[#This Row],[RelativePath]]) -> 1 Ангар Склад 2 въезд\E33149364_6_20251114T133038Z.jpg | N36: =VLOOKUP(склад2въезд[[#This Row],[Name]], СпрСобытий!$F:$G, 2, FALSE) -> Ангар Склад 2 въезд
A37: пт | B37: 45975 | C37: 0.57114583 | D37: Задний ход, въезд на территорию | E37: Самосвал красный | F37: щебень | G37: 1 | I37: E33149364_6_20251114T134227Z.jpg | J37: C:\ВИДЕОНАБЛЮДЕНИЕ\1 Ангар Склад 2 въезд\ | K37: 1 Ангар Склад 2 въезд\E33149364_6_20251114T134227Z.jpg | L37: пт 14.11.2025 — 13:42:27 | M37: =HYPERLINK(склад2въезд[[#This Row],[RelativePath]]) -> 1 Ангар Склад 2 въезд\E33149364_6_20251114T134227Z.jpg | N37: =VLOOKUP(склад2въезд[[#This Row],[Name]], СпрСобытий!$F:$G, 2, FALSE) -> Ангар Склад 2 въезд
A38: пт | B38: 45975 | C38: 0.5740625 | D38: Выезд с территории | E38: Самосвал красный | F38: порожний | I38: E33149364_6_20251114T134639Z.jpg | J38: C:\ВИДЕОНАБЛЮДЕНИЕ\1 Ангар Склад 2 въезд\ | K38: 1 Ангар Склад 2 въезд\E33149364_6_20251114T134639Z.jpg | L38: пт 14.11.2025 — 13:46:39 | M38: =HYPERLINK(склад2въезд[[#This Row],[RelativePath]]) -> 1 Ангар Склад 2 въезд\E33149364_6_20251114T134639Z.jpg | N38: =VLOOKUP(склад2въезд[[#This Row],[Name]], СпрСобытий!$F:$G, 2, FALSE) -> Ангар Склад 2 въезд
A39: пт | B39: 45975 | C39: 0.60061343 | D39: Въезд на базу | E39: Погрузчик базы | F39: порожний | I39: E33149364_6_20251114T142453Z.jpg | J39: C:\ВИДЕОНАБЛЮДЕНИЕ\1 Ангар Склад 2 въезд\ | K39: 1 Ангар Склад 2 въезд\E33149364_6_20251114T142453Z.jpg | L39: пт 14.11.2025 — 14:24:53 | M39: =HYPERLINK(склад2въезд[[#This Row],[RelativePath]]) -> 1 Ангар Склад 2 въезд\E33149364_6_20251114T142453Z.jpg | N39: =VLOOKUP(склад2въезд[[#This Row],[Name]], СпрСобытий!$F:$G, 2, FALSE) -> Ангар Склад 2 въезд
A40: сб | B40: 45976 | C40: 0.43630787 | D40: Въезд на базу | E40: Легковой с прицепом | F40: какой-то агрегат | I40: E33149364_6_20251115T102817Z.jpg | J40: C:\ВИДЕОНАБЛЮДЕНИЕ\1 Ангар Склад 2 въезд\ | K40: 1 Ангар Склад 2 въезд\E33149364_6_20251115T102817Z.jpg | L40: сб 15.11.2025 — 10:28:17 | M40: =HYPERLINK(склад2въезд[[#This Row],[RelativePath]]) -> 1 Ангар Склад 2 въезд\E33149364_6_20251115T102817Z.jpg | N40: =VLOOKUP(склад2въезд[[#This Row],[Name]], СпрСобытий!$F:$G, 2, FALSE) -> Ангар Склад 2 въезд
A41: сб | B41: 45976 | C41: 0.44349537 | D41: Выезд с территории | E41: Погрузчик базы | F41: какой-то агрегат | I41: E33149364_6_20251115T103838Z.jpg | J41: C:\ВИДЕОНАБЛЮДЕНИЕ\1 Ангар Склад 2 въезд\ | K41: 1 Ангар Склад 2 въезд\E33149364_6_20251115T103838Z.jpg | L41: сб 15.11.2025 — 10:38:38 | M41: =HYPERLINK(склад2въезд[[#This Row],[RelativePath]]) -> 1 Ангар Склад 2 въезд\E33149364_6_20251115T103838Z.jpg | N41: =VLOOKUP(склад2въезд[[#This Row],[Name]], СпрСобытий!$F:$G, 2, FALSE) -> Ангар Склад 2 въезд
A42: сб | B42: 45976 | C42: 0.46813657 | D42: Въезд на базу | E42: Трактор желтый | I42: E33149364_6_20251115T111407Z.jpg | J42: C:\ВИДЕОНАБЛЮДЕНИЕ\1 Ангар Склад 2 въезд\ | K42: 1 Ангар Склад 2 въезд\E33149364_6_20251115T111407Z.jpg | L42: сб 15.11.2025 — 11:14:07 | M42: =HYPERLINK(склад2въезд[[#This Row],[RelativePath]]) -> 1 Ангар Склад 2 въезд\E33149364_6_20251115T111407Z.jpg | N42: =VLOOKUP(склад2въезд[[#This Row],[Name]], СпрСобытий!$F:$G, 2, FALSE) -> Ангар Склад 2 въезд
A43: сб | B43: 45976 | C43: 0.49760417 | D43: Выезд с территории | E43: Трактор желтый | I43: E33149364_6_20251115T115633Z.jpg | J43: C:\ВИДЕОНАБЛЮДЕНИЕ\1 Ангар Склад 2 въезд\ | K43: 1 Ангар Склад 2 въезд\E33149364_6_20251115T115633Z.jpg | L43: сб 15.11.2025 — 11:56:33 | M43: =HYPERLINK(склад2въезд[[#This Row],[RelativePath]]) -> 1 Ангар Склад 2 въезд\E33149364_6_20251115T115633Z.jpg | N43: =VLOOKUP(склад2въезд[[#This Row],[Name]], СпрСобытий!$F:$G, 2, FALSE) -> Ангар Склад 2 въезд
A44: сб | B44: 45976 | C44: 0.6228125 | D44: Въезд на базу | E44: Легковая сторонняя | I44: E33149364_6_20251115T145651Z.jpg | J44: C:\ВИДЕОНАБЛЮДЕНИЕ\1 Ангар Склад 2 въезд\ | K44: 1 Ангар Склад 2 въезд\E33149364_6_20251115T145651Z.jpg | L44: сб 15.11.2025 — 14:56:51 | M44: =HYPERLINK(склад2въезд[[#This Row],[RelativePath]]) -> 1 Ангар Склад 2 въезд\E33149364_6_20251115T145651Z.jpg | N44: =VLOOKUP(склад2въезд[[#This Row],[Name]], СпрСобытий!$F:$G, 2, FALSE) -> Ангар Склад 2 въезд
A45: сб | B45: 45976 | C45: 0.63025463 | D45: Въезд на базу | E45: Погрузчик базы | F45: какой-то агрегат | I45: E33149364_6_20251115T150734Z.jpg | J45: C:\ВИДЕОНАБЛЮДЕНИЕ\1 Ангар Склад 2 въезд\ | K45: 1 Ангар Склад 2 въезд\E33149364_6_20251115T150734Z.jpg | L45: сб 15.11.2025 — 15:07:34 | M45: =HYPERLINK(склад2въезд[[#This Row],[RelativePath]]) -> 1 Ангар Склад 2 въезд\E33149364_6_20251115T150734Z.jpg | N45: =VLOOKUP(склад2въезд[[#This Row],[Name]], СпрСобытий!$F:$G, 2, FALSE) -> Ангар Склад 2 въезд
A46: сб | B46: 45976 | C46: 0.64368056 | D46: Выезд с территории | E46: Легковая сторонняя | I46: E33149364_6_20251115T152654Z.jpg | J46: C:\ВИДЕОНАБЛЮДЕНИЕ\1 Ангар Склад 2 въезд\ | K46: 1 Ангар Склад 2 въезд\E33149364_6_20251115T152654Z.jpg | L46: сб 15.11.2025 — 15:26:54 | M46: =HYPERLINK(склад2въезд[[#This Row],[RelativePath]]) -> 1 Ангар Склад 2 въезд\E33149364_6_20251115T152654Z.jpg | N46: =VLOOKUP(склад2въезд[[#This Row],[Name]], СпрСобытий!$F:$G, 2, FALSE) -> Ангар Склад 2 въезд
...

Sheet 2 Пилорама поката
A1: День нед | B1: Дата | C1: Время | D1: Событие | E1: Объект | F1: Груз | G1: Кол-во | H1: Примечание | I1: Name | J1: Folder Path | K1: RelativePath | L1: Подпись | M1: Ссылка на фото
A2: пн | B2: 45971 | C2: 0.39209491 | D2: Фиксация в кадре | E2: Территория | I2: E33149364_7_20251110T092437Z.jpg | J2: C:\ВИДЕОНАБЛЮДЕНИЕ\2 Пилорама поката\ | K2: 2 Пилорама поката\E33149364_7_20251110T092437Z.jpg | L2: пн 10.11.2025 — 09:24:37 | M2: =HYPERLINK(склад2въезд14[[#This Row],[RelativePath]]) -> 2 Пилорама поката\E33149364_7_20251110T092437Z.jpg
A3: пн | B3: 45971 | C3: 0.39253472 | D3: Доставка | E3: Трактор базы | F3: бревна | G3: 2 | I3: E33149364_7_20251110T092515Z.jpg | J3: C:\ВИДЕОНАБЛЮДЕНИЕ\2 Пилорама поката\ | K3: 2 Пилорама поката\E33149364_7_20251110T092515Z.jpg | L3: пн 10.11.2025 — 09:25:15 | M3: =HYPERLINK(склад2въезд14[[#This Row],[RelativePath]]) -> 2 Пилорама поката\E33149364_7_20251110T092515Z.jpg
A4: пн | B4: 45971 | C4: 0.41855324 | D4: Доставка | E4: Трактор базы | F4: бревна | G4: 1 | I4: E33149364_7_20251110T100243Z.jpg | J4: C:\ВИДЕОНАБЛЮДЕНИЕ\2 Пилорама поката\ | K4: 2 Пилорама поката\E33149364_7_20251110T100243Z.jpg | L4: пн 10.11.2025 — 10:02:43 | M4: =HYPERLINK(склад2въезд14[[#This Row],[RelativePath]]) -> 2 Пилорама поката\E33149364_7_20251110T100243Z.jpg
A5: пн | B5: 45971 | C5: 0.43763889 | D5: Доставка | E5: Трактор базы | F5: бревна | G5: 2 | I5: E33149364_7_20251110T103012Z.jpg | J5: C:\ВИДЕОНАБЛЮДЕНИЕ\2 Пилорама поката\ | K5: 2 Пилорама поката\E33149364_7_20251110T103012Z.jpg | L5: пн 10.11.2025 — 10:30:12 | M5: =HYPERLINK(склад2въезд14[[#This Row],[RelativePath]]) -> 2 Пилорама поката\E33149364_7_20251110T103012Z.jpg
A6: пн | B6: 45971 | C6: 0.44165509 | D6: Доставка | E6: Трактор базы | F6: бревна | G6: 2 | I6: E33149364_7_20251110T103559Z.jpg | J6: C:\ВИДЕОНАБЛЮДЕНИЕ\2 Пилорама поката\ | K6: 2 Пилорама поката\E33149364_7_20251110T103559Z.jpg | L6: пн 10.11.2025 — 10:35:59 | M6: =HYPERLINK(склад2въезд14[[#This Row],[RelativePath]]) -> 2 Пилорама поката\E33149364_7_20251110T103559Z.jpg
A7: пн | B7: 45971 | C7: 0.44550926 | D7: Доставка | E7: Трактор базы | F7: бревна | G7: 1 | I7: E33149364_7_20251110T104132Z.jpg | J7: C:\ВИДЕОНАБЛЮДЕНИЕ\2 Пилорама поката\ | K7: 2 Пилорама поката\E33149364_7_20251110T104132Z.jpg | L7: пн 10.11.2025 — 10:41:32 | M7: =HYPERLINK(склад2въезд14[[#This Row],[RelativePath]]) -> 2 Пилорама поката\E33149364_7_20251110T104132Z.jpg
A8: пн | B8: 45971 | C8: 0.45173611 | D8: Доставка | E8: Трактор базы | F8: бревна | G8: 2 | I8: E33149364_7_20251110T105030Z.jpg | J8: C:\ВИДЕОНАБЛЮДЕНИЕ\2 Пилорама поката\ | K8: 2 Пилорама поката\E33149364_7_20251110T105030Z.jpg | L8: пн 10.11.2025 — 10:50:30 | M8: =HYPERLINK(склад2въезд14[[#This Row],[RelativePath]]) -> 2 Пилорама поката\E33149364_7_20251110T105030Z.jpg
A9: пн | B9: 45971 | C9: 0.45603009 | D9: Доставка | E9: Трактор базы | F9: бревна | G9: 1 | I9: E33149364_7_20251110T105641Z.jpg | J9: C:\ВИДЕОНАБЛЮДЕНИЕ\2 Пилорама поката\ | K9: 2 Пилорама поката\E33149364_7_20251110T105641Z.jpg | L9: пн 10.11.2025 — 10:56:41 | M9: =HYPERLINK(склад2въезд14[[#This Row],[RelativePath]]) -> 2 Пилорама поката\E33149364_7_20251110T105641Z.jpg
A10: вт | B10: 45972 | C10: 0.33320602 | D10: Фиксация в кадре | E10: Территория | I10: E33149364_7_20251111T075949Z.jpg | J10: C:\ВИДЕОНАБЛЮДЕНИЕ\2 Пилорама поката\ | K10: 2 Пилорама поката\E33149364_7_20251111T075949Z.jpg | L10: вт 11.11.2025 — 07:59:49 | M10: =HYPERLINK(склад2въезд14[[#This Row],[RelativePath]]) -> 2 Пилорама поката\E33149364_7_20251111T075949Z.jpg
A11: вт | B11: 45972 | C11: 0.35127315 | D11: Фиксация в кадре | E11: Территория | I11: E33149364_7_20251111T082550Z.jpg | J11: C:\ВИДЕОНАБЛЮДЕНИЕ\2 Пилорама поката\ | K11: 2 Пилорама поката\E33149364_7_20251111T082550Z.jpg | L11: вт 11.11.2025 — 08:25:50 | M11: =HYPERLINK(склад2въезд14[[#This Row],[RelativePath]]) -> 2 Пилорама поката\E33149364_7_20251111T082550Z.jpg
A12: вт | B12: 45972 | C12: 0.45701389 | D12: Проезд | E12: Газель бортовая, синяя кабина | F12: порожний | I12: E33149364_7_20251111T105806Z.jpg | J12: C:\ВИДЕОНАБЛЮДЕНИЕ\2 Пилорама поката\ | K12: 2 Пилорама поката\E33149364_7_20251111T105806Z.jpg | L12: вт 11.11.2025 — 10:58:06 | M12: =HYPERLINK(склад2въезд14[[#This Row],[RelativePath]]) -> 2 Пилорама поката\E33149364_7_20251111T105806Z.jpg
A13: вт | B13: 45972 | C13: 0.60871528 | D13: Доставка | E13: Трактор базы | F13: бревна | G13: 1 | I13: E33149364_7_20251111T143633Z.jpg | J13: C:\ВИДЕОНАБЛЮДЕНИЕ\2 Пилорама поката\ | K13: 2 Пилорама поката\E33149364_7_20251111T143633Z.jpg | L13: вт 11.11.2025 — 14:36:33 | M13: =HYPERLINK(склад2въезд14[[#This Row],[RelativePath]]) -> 2 Пилорама поката\E33149364_7_20251111T143633Z.jpg
A14: вт | B14: 45972 | C14: 0.61587963 | D14: Доставка | E14: Трактор базы | F14: бревна | G14: 1 | I14: E33149364_7_20251111T144652Z.jpg | J14: C:\ВИДЕОНАБЛЮДЕНИЕ\2 Пилорама поката\ | K14: 2 Пилорама поката\E33149364_7_20251111T144652Z.jpg | L14: вт 11.11.2025 — 14:46:52 | M14: =HYPERLINK(склад2въезд14[[#This Row],[RelativePath]]) -> 2 Пилорама поката\E33149364_7_20251111T144652Z.jpg
A15: вт | B15: 45972 | C15: 0.62045139 | D15: Доставка | E15: Трактор базы | F15: бревна | G15: 1 | I15: E33149364_7_20251111T145327Z.jpg | J15: C:\ВИДЕОНАБЛЮДЕНИЕ\2 Пилорама поката\ | K15: 2 Пилорама поката\E33149364_7_20251111T145327Z.jpg | L15: вт 11.11.2025 — 14:53:27 | M15: =HYPERLINK(склад2въезд14[[#This Row],[RelativePath]]) -> 2 Пилорама поката\E33149364_7_20251111T145327Z.jpg
A16: вт | B16: 45972 | C16: 0.62636574 | D16: Доставка | E16: Трактор базы | F16: бревна | G16: 2 | I16: E33149364_7_20251111T150158Z.jpg | J16: C:\ВИДЕОНАБЛЮДЕНИЕ\2 Пилорама поката\ | K16: 2 Пилорама поката\E33149364_7_20251111T150158Z.jpg | L16: вт 11.11.2025 — 15:01:58 | M16: =HYPERLINK(склад2въезд14[[#This Row],[RelativePath]]) -> 2 Пилорама поката\E33149364_7_20251111T150158Z.jpg
A17: вт | B17: 45972 | C17: 0.66290509 | D17: Доставка | E17: Трактор базы | F17: бревна | G17: 1 | I17: E33149364_7_20251111T155435Z.jpg | J17: C:\ВИДЕОНАБЛЮДЕНИЕ\2 Пилорама поката\ | K17: 2 Пилорама поката\E33149364_7_20251111T155435Z.jpg | L17: вт 11.11.2025 — 15:54:35 | M17: =HYPERLINK(склад2въезд14[[#This Row],[RelativePath]]) -> 2 Пилорама поката\E33149364_7_20251111T155435Z.jpg
A18: ср | B18: 45973 | C18: 0.76931713 | D18: Фиксация в кадре | E18: Территория | I18: E33149364_7_20251112T182749Z.jpg | J18: C:\ВИДЕОНАБЛЮДЕНИЕ\2 Пилорама поката\ | K18: 2 Пилорама поката\E33149364_7_20251112T182749Z.jpg | L18: ср 12.11.2025 — 18:27:49 | M18: =HYPERLINK(склад2въезд14[[#This Row],[RelativePath]]) -> 2 Пилорама поката\E33149364_7_20251112T182749Z.jpg
A19: чт | B19: 45974 | C19: 0.34604167 | D19: Фиксация в кадре | E19: Территория | I19: E33149364_7_20251113T081818Z.jpg | J19: C:\ВИДЕОНАБЛЮДЕНИЕ\2 Пилорама поката\ | K19: 2 Пилорама поката\E33149364_7_20251113T081818Z.jpg | L19: чт 13.11.2025 — 08:18:18 | M19: =HYPERLINK(склад2въезд14[[#This Row],[RelativePath]]) -> 2 Пилорама поката\E33149364_7_20251113T081818Z.jpg
A20: чт | B20: 45974 | C20: 0.37868056 | D20: Проезд | E20: Газель базы | I20: E33149364_7_20251113T090518Z.jpg | J20: C:\ВИДЕОНАБЛЮДЕНИЕ\2 Пилорама поката\ | K20: 2 Пилорама поката\E33149364_7_20251113T090518Z.jpg | L20: чт 13.11.2025 — 09:05:18 | M20: =HYPERLINK(склад2въезд14[[#This Row],[RelativePath]]) -> 2 Пилорама поката\E33149364_7_20251113T090518Z.jpg
A21: чт | B21: 45974 | C21: 0.68540509 | D21: Доставка | E21: Трактор базы | F21: бревна | G21: 1 | I21: E33149364_7_20251113T162659Z.jpg | J21: C:\ВИДЕОНАБЛЮДЕНИЕ\2 Пилорама поката\ | K21: 2 Пилорама поката\E33149364_7_20251113T162659Z.jpg | L21: чт 13.11.2025 — 16:26:59 | M21: =HYPERLINK(склад2въезд14[[#This Row],[RelativePath]]) -> 2 Пилорама поката\E33149364_7_20251113T162659Z.jpg
A22: чт | B22: 45974 | C22: 0.68618056 | D22: Фиксация в кадре | E22: Трактор, проталкивание бревен внутрь ангара | I22: E33149364_7_20251113T162806Z.jpg | J22: C:\ВИДЕОНАБЛЮДЕНИЕ\2 Пилорама поката\ | K22: 2 Пилорама поката\E33149364_7_20251113T162806Z.jpg | L22: чт 13.11.2025 — 16:28:06 | M22: =HYPERLINK(склад2въезд14[[#This Row],[RelativePath]]) -> 2 Пилорама поката\E33149364_7_20251113T162806Z.jpg
A23: чт | B23: 45974 | C23: 0.71075231 | D23: Фиксация в кадре | E23: Территория | I23: E33149364_7_20251113T170329Z.jpg | J23: C:\ВИДЕОНАБЛЮДЕНИЕ\2 Пилорама поката\ | K23: 2 Пилорама поката\E33149364_7_20251113T170329Z.jpg | L23: чт 13.11.2025 — 17:03:29 | M23: =HYPERLINK(склад2въезд14[[#This Row],[RelativePath]]) -> 2 Пилорама поката\E33149364_7_20251113T170329Z.jpg
A24: пт | B24: 45975 | C24: 0.40074074 | D24: Фиксация в кадре | E24: Территория | I24: E33149364_7_20251114T093704Z.jpg | J24: C:\ВИДЕОНАБЛЮДЕНИЕ\2 Пилорама поката\ | K24: 2 Пилорама поката\E33149364_7_20251114T093704Z.jpg | L24: пт 14.11.2025 — 09:37:04 | M24: =HYPERLINK(склад2въезд14[[#This Row],[RelativePath]]) -> 2 Пилорама поката\E33149364_7_20251114T093704Z.jpg
A25: пт | B25: 45975 | C25: 0.40642361 | D25: Проезд | E25: Трактор базы | F25: отрезки бревен | I25: E33149364_7_20251114T094515Z.jpg | J25: C:\ВИДЕОНАБЛЮДЕНИЕ\2 Пилорама поката\ | K25: 2 Пилорама поката\E33149364_7_20251114T094515Z.jpg | L25: пт 14.11.2025 — 09:45:15 | M25: =HYPERLINK(склад2въезд14[[#This Row],[RelativePath]]) -> 2 Пилорама поката\E33149364_7_20251114T094515Z.jpg
A26: пт | B26: 45975 | C26: 0.42190972 | D26: Проезд | E26: Трактор базы | F26: отрезки бревен | I26: E33149364_7_20251114T100733Z.jpg | J26: C:\ВИДЕОНАБЛЮДЕНИЕ\2 Пилорама поката\ | K26: 2 Пилорама поката\E33149364_7_20251114T100733Z.jpg | L26: пт 14.11.2025 — 10:07:33 | M26: =HYPERLINK(склад2въезд14[[#This Row],[RelativePath]]) -> 2 Пилорама поката\E33149364_7_20251114T100733Z.jpg
A27: пт | B27: 45975 | C27: 0.42277778 | D27: Обратный проезд | E27: Трактор базы | F27: порожний | I27: E33149364_7_20251114T100848Z.jpg | J27: C:\ВИДЕОНАБЛЮДЕНИЕ\2 Пилорама поката\ | K27: 2 Пилорама поката\E33149364_7_20251114T100848Z.jpg | L27: пт 14.11.2025 — 10:08:48 | M27: =HYPERLINK(склад2въезд14[[#This Row],[RelativePath]]) -> 2 Пилорама поката\E33149364_7_20251114T100848Z.jpg
A28: пт | B28: 45975 | C28: 0.48237269 | D28: Проезд | E28: Трактор базы | F28: отрезки бревен | I28: E33149364_7_20251114T113437Z.jpg | J28: C:\ВИДЕОНАБЛЮДЕНИЕ\2 Пилорама поката\ | K28: 2 Пилорама поката\E33149364_7_20251114T113437Z.jpg | L28: пт 14.11.2025 — 11:34:37 | M28: =HYPERLINK(склад2въезд14[[#This Row],[RelativePath]]) -> 2 Пилорама поката\E33149364_7_20251114T113437Z.jpg
A29: пт | B29: 45975 | C29: 0.49148148 | D29: Проезд | E29: Трактор базы | F29: отрезки бревен | I29: E33149364_7_20251114T114744Z.jpg | J29: C:\ВИДЕОНАБЛЮДЕНИЕ\2 Пилорама поката\ | K29: 2 Пилорама поката\E33149364_7_20251114T114744Z.jpg | L29: пт 14.11.2025 — 11:47:44 | M29: =HYPERLINK(склад2въезд14[[#This Row],[RelativePath]]) -> 2 Пилорама поката\E33149364_7_20251114T114744Z.jpg
A30: пт | B30: 45975 | C30: 0.49703704 | D30: Доставка | E30: Трактор базы | F30: бревна | G30: 1 | I30: E33149364_7_20251114T115544Z.jpg | J30: C:\ВИДЕОНАБЛЮДЕНИЕ\2 Пилорама поката\ | K30: 2 Пилорама поката\E33149364_7_20251114T115544Z.jpg | L30: пт 14.11.2025 — 11:55:44 | M30: =HYPERLINK(склад2въезд14[[#This Row],[RelativePath]]) -> 2 Пилорама поката\E33149364_7_20251114T115544Z.jpg
A31: пт | B31: 45975 | C31: 0.50545139 | D31: Проезд | E31: Трактор базы | F31: отрезки бревен | I31: E33149364_7_20251114T120751Z.jpg | J31: C:\ВИДЕОНАБЛЮДЕНИЕ\2 Пилорама поката\ | K31: 2 Пилорама поката\E33149364_7_20251114T120751Z.jpg | L31: пт 14.11.2025 — 12:07:51 | M31: =HYPERLINK(склад2въезд14[[#This Row],[RelativePath]]) -> 2 Пилорама поката\E33149364_7_20251114T120751Z.jpg
A32: пт | B32: 45975 | C32: 0.51671296 | D32: Проезд | E32: Трактор базы | F32: отрезки бревен | I32: E33149364_7_20251114T122404Z.jpg | J32: C:\ВИДЕОНАБЛЮДЕНИЕ\2 Пилорама поката\ | K32: 2 Пилорама поката\E33149364_7_20251114T122404Z.jpg | L32: пт 14.11.2025 — 12:24:04 | M32: =HYPERLINK(склад2въезд14[[#This Row],[RelativePath]]) -> 2 Пилорама поката\E33149364_7_20251114T122404Z.jpg
A33: пт | B33: 45975 | C33: 0.5296412 | D33: Проезд | E33: Трактор базы | F33: отрезки бревен | I33: E33149364_7_20251114T124241Z.jpg | J33: C:\ВИДЕОНАБЛЮДЕНИЕ\2 Пилорама поката\ | K33: 2 Пилорама поката\E33149364_7_20251114T124241Z.jpg | L33: пт 14.11.2025 — 12:42:41 | M33: =HYPERLINK(склад2въезд14[[#This Row],[RelativePath]]) -> 2 Пилорама поката\E33149364_7_20251114T124241Z.jpg
A34: пт | B34: 45975 | C34: 0.53068287 | D34: Выезд по второстепенной дороги | E34: Трактор базы | F34: порожний | I34: E33149364_7_20251114T124411Z.jpg | J34: C:\ВИДЕОНАБЛЮДЕНИЕ\2 Пилорама поката\ | K34: 2 Пилорама поката\E33149364_7_20251114T124411Z.jpg | L34: пт 14.11.2025 — 12:44:11 | M34: =HYPERLINK(склад2въезд14[[#This Row],[RelativePath]]) -> 2 Пилорама поката\E33149364_7_20251114T124411Z.jpg
A35: пт | B35: 45975 | C35: 0.5409838 | D35: Проезд | E35: Трактор базы | F35: шина | I35: E33149364_7_20251114T125901Z.jpg | J35: C:\ВИДЕОНАБЛЮДЕНИЕ\2 Пилорама поката\ | K35: 2 Пилорама поката\E33149364_7_20251114T125901Z.jpg | L35: пт 14.11.2025 — 12:59:01 | M35: =HYPERLINK(склад2въезд14[[#This Row],[RelativePath]]) -> 2 Пилорама поката\E33149364_7_20251114T125901Z.jpg
A36: пт | B36: 45975 | C36: 0.74130787 | D36: Фиксация в кадре | E36: Территория | I36: E33149364_7_20251114T174729Z.jpg | J36: C:\ВИДЕОНАБЛЮДЕНИЕ\2 Пилорама поката\ | K36: 2 Пилорама поката\E33149364_7_20251114T174729Z.jpg | L36: пт 14.11.2025 — 17:47:29 | M36: =HYPERLINK(склад2въезд14[[#This Row],[RelativePath]]) -> 2 Пилорама поката\E33149364_7_20251114T174729Z.jpg
A37: сб | B37: 45976 | C37: 0.35449074 | D37: Фиксация в кадре | E37: Территория | H37: без событий | I37: E33149364_7_20251115T083028Z.jpg | J37: C:\ВИДЕОНАБЛЮДЕНИЕ\2 Пилорама поката\ | K37: 2 Пилорама поката\E33149364_7_20251115T083028Z.jpg | L37: сб 15.11.2025 — 08:30:28 | M37: =HYPERLINK(склад2въезд14[[#This Row],[RelativePath]]) -> 2 Пилорама поката\E33149364_7_20251115T083028Z.jpg
A38: сб | B38: 45976 | C38: 0.7337963 | D38: Фиксация в кадре | E38: Территория | I38: E33149364_7_20251115T173640Z.jpg | J38: C:\ВИДЕОНАБЛЮДЕНИЕ\2 Пилорама поката\ | K38: 2 Пилорама поката\E33149364_7_20251115T173640Z.jpg | L38: сб 15.11.2025 — 17:36:40 | M38: =HYPERLINK(склад2въезд14[[#This Row],[RelativePath]]) -> 2 Пилорама поката\E33149364_7_20251115T173640Z.jpg
A39: вс | B39: 45977 | C39: 0.39959491 | D39: Фиксация в кадре | E39: Территория | H39: без событий | I39: E33149364_7_20251116T093525Z.jpg | J39: C:\ВИДЕОНАБЛЮДЕНИЕ\2 Пилорама поката\ | K39: 2 Пилорама поката\E33149364_7_20251116T093525Z.jpg | L39: вс 16.11.2025 — 09:35:25 | M39: =HYPERLINK(склад2въезд14[[#This Row],[RelativePath]]) -> 2 Пилорама поката\E33149364_7_20251116T093525Z.jpg
A40: вс | B40: 45977 | C40: 0.74412037 | D40: Фиксация в кадре | E40: Территория | I40: E33149364_7_20251116T175132Z.jpg | J40: C:\ВИДЕОНАБЛЮДЕНИЕ\2 Пилорама поката\ | K40: 2 Пилорама поката\E33149364_7_20251116T175132Z.jpg | L40: вс 16.11.2025 — 17:51:32 | M40: =HYPERLINK(склад2въезд14[[#This Row],[RelativePath]]) -> 2 Пилорама поката\E33149364_7_20251116T175132Z.jpg
...

Sheet 3 Парковка офиса
A1: День нед | B1: Дата | C1: Время | D1: Событие | E1: Объект | F1: Груз | G1: Кол-во | H1: Примечание | I1: Name | J1: Folder Path | K1: RelativePath | L1: Подпись | M1: Ссылка на фото
A2: пн | B2: 45971 | C2: 0.35270833 | D2: Фиксация в кадре | E2: Территория | I2: E33149364_8_20251110T082754Z.jpg | J2: C:\ВИДЕОНАБЛЮДЕНИЕ\3 Парковка офиса\ | K2: 3 Парковка офиса\E33149364_8_20251110T082754Z.jpg | L2: пн 10.11.2025 — 08:27:54 | M2: =HYPERLINK(склад2въезд18[[#This Row],[RelativePath]]) -> 3 Парковка офиса\E33149364_8_20251110T082754Z.jpg
A3: пн | B3: 45971 | C3: 0.37762731 | D3: Фиксация в кадре | E3: Территория | I3: E33149364_8_20251110T090347Z.jpg | J3: C:\ВИДЕОНАБЛЮДЕНИЕ\3 Парковка офиса\ | K3: 3 Парковка офиса\E33149364_8_20251110T090347Z.jpg | L3: пн 10.11.2025 — 09:03:47 | M3: =HYPERLINK(склад2въезд18[[#This Row],[RelativePath]]) -> 3 Парковка офиса\E33149364_8_20251110T090347Z.jpg
A4: пн | B4: 45971 | C4: 0.48642361 | D4: Фиксация в кадре | E4: Территория | I4: E33149364_8_20251110T114027Z.jpg | J4: C:\ВИДЕОНАБЛЮДЕНИЕ\3 Парковка офиса\ | K4: 3 Парковка офиса\E33149364_8_20251110T114027Z.jpg | L4: пн 10.11.2025 — 11:40:27 | M4: =HYPERLINK(склад2въезд18[[#This Row],[RelativePath]]) -> 3 Парковка офиса\E33149364_8_20251110T114027Z.jpg
A5: пн | B5: 45971 | C5: 0.50173611 | D5: Фиксация в кадре | E5: Территория | I5: E33149364_8_20251110T120230Z.jpg | J5: C:\ВИДЕОНАБЛЮДЕНИЕ\3 Парковка офиса\ | K5: 3 Парковка офиса\E33149364_8_20251110T120230Z.jpg | L5: пн 10.11.2025 — 12:02:30 | M5: =HYPERLINK(склад2въезд18[[#This Row],[RelativePath]]) -> 3 Парковка офиса\E33149364_8_20251110T120230Z.jpg
A6: пн | B6: 45971 | C6: 0.56997685 | D6: Фиксация в кадре | E6: Территория | I6: E33149364_8_20251110T134046Z.jpg | J6: C:\ВИДЕОНАБЛЮДЕНИЕ\3 Парковка офиса\ | K6: 3 Парковка офиса\E33149364_8_20251110T134046Z.jpg | L6: пн 10.11.2025 — 13:40:46 | M6: =HYPERLINK(склад2въезд18[[#This Row],[RelativePath]]) -> 3 Парковка офиса\E33149364_8_20251110T134046Z.jpg
A7: пн | B7: 45971 | C7: 0.7184375 | D7: Фиксация в кадре | E7: Территория | I7: E33149364_8_20251110T171433Z.jpg | J7: C:\ВИДЕОНАБЛЮДЕНИЕ\3 Парковка офиса\ | K7: 3 Парковка офиса\E33149364_8_20251110T171433Z.jpg | L7: пн 10.11.2025 — 17:14:33 | M7: =HYPERLINK(склад2въезд18[[#This Row],[RelativePath]]) -> 3 Парковка офиса\E33149364_8_20251110T171433Z.jpg
A8: вт | B8: 45972 | C8: 0.39150463 | D8: Фиксация в кадре | E8: Территория | I8: E33149364_8_20251111T092346Z.jpg | J8: C:\ВИДЕОНАБЛЮДЕНИЕ\3 Парковка офиса\ | K8: 3 Парковка офиса\E33149364_8_20251111T092346Z.jpg | L8: вт 11.11.2025 — 09:23:46 | M8: =HYPERLINK(склад2въезд18[[#This Row],[RelativePath]]) -> 3 Парковка офиса\E33149364_8_20251111T092346Z.jpg
A9: вт | B9: 45972 | C9: 0.44740741 | D9: Фиксация в кадре | E9: Территория | I9: E33149364_8_20251111T104416Z.jpg | J9: C:\ВИДЕОНАБЛЮДЕНИЕ\3 Парковка офиса\ | K9: 3 Парковка офиса\E33149364_8_20251111T104416Z.jpg | L9: вт 11.11.2025 — 10:44:16 | M9: =HYPERLINK(склад2въезд18[[#This Row],[RelativePath]]) -> 3 Парковка офиса\E33149364_8_20251111T104416Z.jpg
A10: вт | B10: 45972 | C10: 0.45055556 | D10: Фиксация в кадре | E10: Территория | I10: E33149364_8_20251111T104848Z.jpg | J10: C:\ВИДЕОНАБЛЮДЕНИЕ\3 Парковка офиса\ | K10: 3 Парковка офиса\E33149364_8_20251111T104848Z.jpg | L10: вт 11.11.2025 — 10:48:48 | M10: =HYPERLINK(склад2въезд18[[#This Row],[RelativePath]]) -> 3 Парковка офиса\E33149364_8_20251111T104848Z.jpg
A11: вт | B11: 45972 | C11: 0.48456019 | D11: Фиксация в кадре | E11: Территория | I11: E33149364_8_20251111T113746Z.jpg | J11: C:\ВИДЕОНАБЛЮДЕНИЕ\3 Парковка офиса\ | K11: 3 Парковка офиса\E33149364_8_20251111T113746Z.jpg | L11: вт 11.11.2025 — 11:37:46 | M11: =HYPERLINK(склад2въезд18[[#This Row],[RelativePath]]) -> 3 Парковка офиса\E33149364_8_20251111T113746Z.jpg
A12: вт | B12: 45972 | C12: 0.48466435 | D12: Фиксация в кадре | E12: Территория | I12: E33149364_8_20251111T113755Z.jpg | J12: C:\ВИДЕОНАБЛЮДЕНИЕ\3 Парковка офиса\ | K12: 3 Парковка офиса\E33149364_8_20251111T113755Z.jpg | L12: вт 11.11.2025 — 11:37:55 | M12: =HYPERLINK(склад2въезд18[[#This Row],[RelativePath]]) -> 3 Парковка офиса\E33149364_8_20251111T113755Z.jpg
A13: вт | B13: 45972 | C13: 0.53394676 | D13: Фиксация в кадре | E13: Территория | I13: E33149364_8_20251111T124853Z.jpg | J13: C:\ВИДЕОНАБЛЮДЕНИЕ\3 Парковка офиса\ | K13: 3 Парковка офиса\E33149364_8_20251111T124853Z.jpg | L13: вт 11.11.2025 — 12:48:53 | M13: =HYPERLINK(склад2въезд18[[#This Row],[RelativePath]]) -> 3 Парковка офиса\E33149364_8_20251111T124853Z.jpg
... A16: ср | B16: 45973 | C16: 0.6775463 | D16: Фиксация в кадре | E16: Территория | I16: E33149364_8_20251112T161540Z.jpg | J16: C:\ВИДЕОНАБЛЮДЕНИЕ\3 Парковка офиса\ | K16: 3 Парковка офиса\E33149364_8_20251112T161540Z.jpg | L16: ср 12.11.2025 — 16:15:40 | M16: =HYPERLINK(склад2въезд18[[#This Row],[RelativePath]]) -> 3 Парковка офиса\E33149364_8_20251112T161540Z.jpg
A17: ср | B17: 45973 | C17: 0.68575231 | D17: Загрузка | E17: Самосвал красный | F17: земля с территории | I17: E33149364_8_20251112T162729Z.jpg | J17: C:\ВИДЕОНАБЛЮДЕНИЕ\3 Парковка офиса\ | K17: 3 Парковка офиса\E33149364_8_20251112T162729Z.jpg | L17: ср 12.11.2025 — 16:27:29 | M17: =HYPERLINK(склад2въезд18[[#This Row],[RelativePath]]) -> 3 Парковка офиса\E33149364_8_20251112T162729Z.jpg
A18: ср | B18: 45973 | C18: 0.71013889 | D18: Фиксация в кадре | E18: Территория | I18: E33149364_8_20251112T170236Z.jpg | J18: C:\ВИДЕОНАБЛЮДЕНИЕ\3 Парковка офиса\ | K18: 3 Парковка офиса\E33149364_8_20251112T170236Z.jpg | L18: ср 12.11.2025 — 17:02:36 | M18: =HYPERLINK(склад2въезд18[[#This Row],[RelativePath]]) -> 3 Парковка офиса\E33149364_8_20251112T170236Z.jpg
A19: ср | B19: 45973 | C19: 0.73420139 | D19: Фиксация в кадре | E19: Территория | I19: E33149364_8_20251112T173715Z.jpg | J19: C:\ВИДЕОНАБЛЮДЕНИЕ\3 Парковка офиса\ | K19: 3 Парковка офиса\E33149364_8_20251112T173715Z.jpg | L19: ср 12.11.2025 — 17:37:15 | M19: =HYPERLINK(склад2въезд18[[#This Row],[RelativePath]]) -> 3 Парковка офиса\E33149364_8_20251112T173715Z.jpg
A20: чт | B20: 45974 | C20: 0.37181713 | D20: Фиксация в кадре | E20: Территория | I20: E33149364_8_20251113T085525Z.jpg | J20: C:\ВИДЕОНАБЛЮДЕНИЕ\3 Парковка офиса\ | K20: 3 Парковка офиса\E33149364_8_20251113T085525Z.jpg | L20: чт 13.11.2025 — 08:55:25 | M20: =HYPERLINK(склад2въезд18[[#This Row],[RelativePath]]) -> 3 Парковка офиса\E33149364_8_20251113T085525Z.jpg
A21: чт | B21: 45974 | C21: 0.39616898 | D21: Фиксация в кадре | E21: Территория | I21: E33149364_8_20251113T093029Z.jpg | J21: C:\ВИДЕОНАБЛЮДЕНИЕ\3 Парковка офиса\ | K21: 3 Парковка офиса\E33149364_8_20251113T093029Z.jpg | L21: чт 13.11.2025 — 09:30:29 | M21: =HYPERLINK(склад2въезд18[[#This Row],[RelativePath]]) -> 3 Парковка офиса\E33149364_8_20251113T093029Z.jpg
A22: чт | B22: 45974 | C22: 0.39884259 | D22: Фиксация в кадре | E22: Территория | I22: E33149364_8_20251113T093420Z.jpg | J22: C:\ВИДЕОНАБЛЮДЕНИЕ\3 Парковка офиса\ | K22: 3 Парковка офиса\E33149364_8_20251113T093420Z.jpg | L22: чт 13.11.2025 — 09:34:20 | M22: =HYPERLINK(склад2въезд18[[#This Row],[RelativePath]]) -> 3 Парковка офиса\E33149364_8_20251113T093420Z.jpg
A23: чт | B23: 45974 | C23: 0.52461806 | D23: Фиксация в кадре | E23: Территория | I23: E33149364_8_20251113T123527Z.jpg | J23: C:\ВИДЕОНАБЛЮДЕНИЕ\3 Парковка офиса\ | K23: 3 Парковка офиса\E33149364_8_20251113T123527Z.jpg | L23: чт 13.11.2025 — 12:35:27 | M23: =HYPERLINK(склад2въезд18[[#This Row],[RelativePath]]) -> 3 Парковка офиса\E33149364_8_20251113T123527Z.jpg
A24: чт | B24: 45974 | C24: 0.60538194 | D24: Фиксация в кадре | E24: Территория | I24: E33149364_8_20251113T143145Z.jpg | J24: C:\ВИДЕОНАБЛЮДЕНИЕ\3 Парковка офиса\ | K24: 3 Парковка офиса\E33149364_8_20251113T143145Z.jpg | L24: чт 13.11.2025 — 14:31:45 | M24: =HYPERLINK(склад2въезд18[[#This Row],[RelativePath]]) -> 3 Парковка офиса\E33149364_8_20251113T143145Z.jpg
A25: чт | B25: 45974 | C25: 0.72965278 | D25: Фиксация в кадре | E25: Территория | I25: E33149364_8_20251113T173042Z.jpg | J25: C:\ВИДЕОНАБЛЮДЕНИЕ\3 Парковка офиса\ | K25: 3 Парковка офиса\E33149364_8_20251113T173042Z.jpg | L25: чт 13.11.2025 — 17:30:42 | M25: =HYPERLINK(склад2въезд18[[#This Row],[RelativePath]]) -> 3 Парковка офиса\E33149364_8_20251113T173042Z.jpg
A26: пт | B26: 45975 | C26: 0.39704861 | D26: Фиксация в кадре | E26: Территория | I26: E33149364_8_20251114T093145Z.jpg | J26: C:\ВИДЕОНАБЛЮДЕНИЕ\3 Парковка офиса\ | K26: 3 Парковка офиса\E33149364_8_20251114T093145Z.jpg | L26: пт 14.11.2025 — 09:31:45 | M26: =HYPERLINK(склад2въезд18[[#This Row],[RelativePath]]) -> 3 Парковка офиса\E33149364_8_20251114T093145Z.jpg
A27: пт | B27: 45975 | C27: 0.55263889 | D27: Разгрузка | E27: Самосвал красный | F27: щебень | I27: E33149364_8_20251114T131548Z.jpg | J27: C:\ВИДЕОНАБЛЮДЕНИЕ\3 Парковка офиса\ | K27: 3 Парковка офиса\E33149364_8_20251114T131548Z.jpg | L27: пт 14.11.2025 — 13:15:48 | M27: =HYPERLINK(склад2въезд18[[#This Row],[RelativePath]]) -> 3 Парковка офиса\E33149364_8_20251114T131548Z.jpg
A28: пт | B28: 45975 | C28: 0.57384259 | D28: Фиксация в кадре | E28: Территория | I28: E33149364_8_20251114T134620Z.jpg | J28: C:\ВИДЕОНАБЛЮДЕНИЕ\3 Парковка офиса\ | K28: 3 Парковка офиса\E33149364_8_20251114T134620Z.jpg | L28: пт 14.11.2025 — 13:46:20 | M28: =HYPERLINK(склад2въезд18[[#This Row],[RelativePath]]) -> 3 Парковка офиса\E33149364_8_20251114T134620Z.jpg
A29: пт | B29: 45975 | C29: 0.7284375 | D29: Фиксация в кадре | E29: Территория | I29: E33149364_8_20251114T172857Z.jpg | J29: C:\ВИДЕОНАБЛЮДЕНИЕ\3 Парковка офиса\ | K29: 3 Парковка офиса\E33149364_8_20251114T172857Z.jpg | L29: пт 14.11.2025 — 17:28:57 | M29: =HYPERLINK(склад2въезд18[[#This Row],[RelativePath]]) -> 3 Парковка офиса\E33149364_8_20251114T172857Z.jpg
A30: сб | B30: 45976 | C30: 0.43643519 | D30: Фиксация в кадре | E30: Территория | I30: E33149364_8_20251115T102828Z.jpg | J30: C:\ВИДЕОНАБЛЮДЕНИЕ\3 Парковка офиса\ | K30: 3 Парковка офиса\E33149364_8_20251115T102828Z.jpg | L30: сб 15.11.2025 — 10:28:28 | M30: =HYPERLINK(склад2въезд18[[#This Row],[RelativePath]]) -> 3 Парковка офиса\E33149364_8_20251115T102828Z.jpg
A31: сб | B31: 45976 | C31: 0.46833333 | D31: Фиксация в кадре | E31: Территория, работа трактора | H31: начало работы | I31: E33149364_8_20251115T111424Z.jpg | J31: C:\ВИДЕОНАБЛЮДЕНИЕ\3 Парковка офиса\ | K31: 3 Парковка офиса\E33149364_8_20251115T111424Z.jpg | L31: сб 15.11.2025 — 11:14:24 | M31: =HYPERLINK(склад2въезд18[[#This Row],[RelativePath]]) -> 3 Парковка офиса\E33149364_8_20251115T111424Z.jpg
A32: сб | B32: 45976 | C32: 0.4975 | D32: Фиксация в кадре | E32: Территория, работа трактора | H32: окончание работы | I32: E33149364_8_20251115T115624Z.jpg | J32: C:\ВИДЕОНАБЛЮДЕНИЕ\3 Парковка офиса\ | K32: 3 Парковка офиса\E33149364_8_20251115T115624Z.jpg | L32: сб 15.11.2025 — 11:56:24 | M32: =HYPERLINK(склад2въезд18[[#This Row],[RelativePath]]) -> 3 Парковка офиса\E33149364_8_20251115T115624Z.jpg
A33: сб | B33: 45976 | C33: 0.63564815 | D33: Фиксация в кадре | E33: Легковой с прицепом | H33: рядом с отрезками бревен | I33: E33149364_8_20251115T151520Z.jpg | J33: C:\ВИДЕОНАБЛЮДЕНИЕ\3 Парковка офиса\ | K33: 3 Парковка офиса\E33149364_8_20251115T151520Z.jpg | L33: сб 15.11.2025 — 15:15:20 | M33: =HYPERLINK(склад2въезд18[[#This Row],[RelativePath]]) -> 3 Парковка офиса\E33149364_8_20251115T151520Z.jpg
A34: сб | B34: 45976 | C34: 0.64347222 | D34: Фиксация в кадре | E34: Территория | I34: E33149364_8_20251115T152636Z.jpg | J34: C:\ВИДЕОНАБЛЮДЕНИЕ\3 Парковка офиса\ | K34: 3 Парковка офиса\E33149364_8_20251115T152636Z.jpg | L34: сб 15.11.2025 — 15:26:36 | M34: =HYPERLINK(склад2въезд18[[#This Row],[RelativePath]]) -> 3 Парковка офиса\E33149364_8_20251115T152636Z.jpg
A35: сб | B35: 45976 | C35: 0.72960648 | D35: Фиксация в кадре | E35: Территория | H35: конец дня | I35: E33149364_8_20251115T173038Z.jpg | J35: C:\ВИДЕОНАБЛЮДЕНИЕ\3 Парковка офиса\ | K35: 3 Парковка офиса\E33149364_8_20251115T173038Z.jpg | L35: сб 15.11.2025 — 17:30:38 | M35: =HYPERLINK(склад2въезд18[[#This Row],[RelativePath]]) -> 3 Парковка офиса\E33149364_8_20251115T173038Z.jpg
A36: вс | B36: 45977 | C36: 0.36952546 | D36: Фиксация в кадре | E36: Территория | H36: начало дня | I36: E33149364_8_20251116T085207Z.jpg | J36: C:\ВИДЕОНАБЛЮДЕНИЕ\3 Парковка офиса\ | K36: 3 Парковка офиса\E33149364_8_20251116T085207Z.jpg | L36: вс 16.11.2025 — 08:52:07 | M36: =HYPERLINK(склад2въезд18[[#This Row],[RelativePath]]) -> 3 Парковка офиса\E33149364_8_20251116T085207Z.jpg
A37: вс | B37: 45977 | C37: 0.59351852 | D37: Фиксация в кадре | E37: Территория | H37: без событий | I37: E33149364_8_20251116T141440Z.jpg | J37: C:\ВИДЕОНАБЛЮДЕНИЕ\3 Парковка офиса\ | K37: 3 Парковка офиса\E33149364_8_20251116T141440Z.jpg | L37: вс 16.11.2025 — 14:14:40 | M37: =HYPERLINK(склад2въезд18[[#This Row],[RelativePath]]) -> 3 Парковка офиса\E33149364_8_20251116T141440Z.jpg
A38: вс | B38: 45977 | C38: 0.71975694 | D38: Фиксация в кадре | E38: Территория | H38: конец дня | I38: E33149364_8_20251116T171627Z.jpg | J38: C:\ВИДЕОНАБЛЮДЕНИЕ\3 Парковка офиса\ | K38: 3 Парковка офиса\E33149364_8_20251116T171627Z.jpg | L38: вс 16.11.2025 — 17:16:27 | M38: =HYPERLINK(склад2въезд18[[#This Row],[RelativePath]]) -> 3 Парковка офиса\E33149364_8_20251116T171627Z.jpg
A39: пн | B39: 45978 | C39: 0.72520833 | D39: без событий | I39: E33149364_8_20251117T172418Z.jpg | J39: C:\ВИДЕОНАБЛЮДЕНИЕ\3 Парковка офиса\ | K39: 3 Парковка офиса\E33149364_8_20251117T172418Z.jpg | L39: пн 17.11.2025 — 17:24:18 | M39: =HYPERLINK(склад2въезд18[[#This Row],[RelativePath]]) -> 3 Парковка офиса\E33149364_8_20251117T172418Z.jpg
A40: вт | B40: 45979 | C40: 0.37560185 | D40: Фиксация в кадре | E40: Территория | I40: E33149364_8_20251118T090052Z.jpg | J40: C:\ВИДЕОНАБЛЮДЕНИЕ\3 Парковка офиса\ | K40: 3 Парковка офиса\E33149364_8_20251118T090052Z.jpg | L40: вт 18.11.2025 — 09:00:52 | M40: =HYPERLINK(склад2въезд18[[#This Row],[RelativePath]]) -> 3 Парковка офиса\E33149364_8_20251118T090052Z.jpg
A41: вт | B41: 45979 | C41: 0.58296296 | D41: Загрузка | E41: Легковая | F41: доски | H41: на крыше | I41: E33149364_8_20251118T135928Z.jpg | J41: C:\ВИДЕОНАБЛЮДЕНИЕ\3 Парковка офиса\ | K41: 3 Парковка офиса\E33149364_8_20251118T135928Z.jpg | L41: вт 18.11.2025 — 13:59:28 | M41: =HYPERLINK(склад2въезд18[[#This Row],[RelativePath]]) -> 3 Парковка офиса\E33149364_8_20251118T135928Z.jpg
A42: ср | B42: 45980 | C42: 0.49180556 | D42: Фиксация в кадре | E42: Территория | I42: E33149364_8_20251119T114812Z.jpg | J42: C:\ВИДЕОНАБЛЮДЕНИЕ\3 Парковка офиса\ | K42: 3 Парковка офиса\E33149364_8_20251119T114812Z.jpg | L42: ср 19.11.2025 — 11:48:12 | M42: =HYPERLINK(склад2въезд18[[#This Row],[RelativePath]]) -> 3 Парковка офиса\E33149364_8_20251119T114812Z.jpg
...

Sheet СпрСобытий
A1: Событие | B1: Объект | C1: Груз | D1: Кол-во | E1: Примечание | F1: Name | G1: Наименование точки
A2: Выезд с территории | B2: Погрузчик базы | C2: порожний | F2: E33149364_6_20251110T115231Z.jpg | G2: Ангар Склад 2 въезд
A3: Въезд на базу | B3: Легковой с прицепом | C3: порожний | F3: E33149364_6_20251110T120047Z.jpg | G3: Ангар Склад 2 въезд
A4: Въезд на базу | B4: Легковой с прицепом | C4: порожний | F4: E33149364_6_20251110T120052Z.jpg | G4: Ангар Склад 2 въезд
A5: Выезд с территории | B5: Легковой с прицепом | C5: мешки с опилками | D5: 3 | F5: E33149364_6_20251110T122835Z.jpg | G5: Ангар Склад 2 въезд
A6: Въезд на базу | B6: Погрузчик базы | C6: доски | F6: E33149364_6_20251110T134029Z.jpg | G6: Ангар Склад 2 въезд
A7: Выезд с территории | B7: Погрузчик базы | C7: доски | E7: груз один и тот же | F7: E33149364_6_20251110T134540Z.jpg | G7: Ангар Склад 2 въезд
A8: Въезд на базу | B8: Погрузчик базы | C8: доски | E8: груз один и тот же | F8: E33149364_6_20251110T143236Z.jpg | G8: Ангар Склад 2 въезд
A9: Въезд на базу | B9: Погрузчик, желтый | C9: порожний | F9: E33149364_6_20251111T092327Z.jpg | G9: Ангар Склад 2 въезд
A10: Выезд с территории | B10: Погрузчик, желтый | C10: бревна со сруба | F10: E33149364_6_20251111T104437Z.jpg | G10: Ангар Склад 2 въезд
A11: Въезд на базу | B11: Газель бортовая, синяя кабина | C11: порожний | F11: E33149364_6_20251111T104712Z.jpg | G11: Ангар Склад 2 въезд
A12: Задний ход, въезд на территорию | B12: Газель бортовая, синяя кабина | C12: порожний | F12: E33149364_6_20251111T104942Z.jpg | G12: Ангар Склад 2 въезд
A13: Въезд на второстепенную дорогу | B13: Газель бортовая, синяя кабина | C13: порожний | F13: E33149364_6_20251111T104958Z.jpg | G13: Ангар Склад 2 въезд
A14: Выезд с территории | B14: Газель бортовая, синяя кабина | C14: доски | F14: E33149364_6_20251111T113804Z.jpg | G14: Ангар Склад 2 въезд
A15: Выезд с территории | B15: Погрузчик базы | C15: красные доски, тюки | F15: E33149364_6_20251111T125226Z.jpg | G15: Ангар Склад 2 въезд
A16: Въезд на базу | B16: Погрузчик базы | C16: порожний | F16: E33149364_6_20251111T154349Z.jpg | G16: Ангар Склад 2 въезд
A17: Въезд на базу | B17: Самосвал красный | C17: не видно, что находится в кузове | F17: E33149364_6_20251112T161438Z.jpg | G17: Ангар Склад 2 въезд
A18: Выезд с территории | B18: Самосвал красный | C18: земля | F18: E33149364_6_20251112T170242Z.jpg | G18: Ангар Склад 2 въезд
A19: Выезд с территории | B19: Погрузчик базы | C19: порожний | F19: E33149364_6_20251113T084904Z.jpg | G19: Ангар Склад 2 въезд
A20: Въезд на базу | B20: Газель базы | C20: порожний | F20: E33149364_6_20251113T085509Z.jpg | G20: Ангар Склад 2 въезд
... A27: Выезд со второстепенной дороги | B27: Трактор базы | C27: порожний | F27: E33149364_6_20251114T124506Z.jpg | G27: Ангар Склад 2 въезд
A28: Въезд на базу | B28: Трактор базы | C28: шина | D28: 1 | F28: E33149364_6_20251114T125035Z.jpg | G28: Ангар Склад 2 въезд
A29: Выезд с территории | B29: Трактор базы | C29: порожний | F29: E33149364_6_20251114T125414Z.jpg | G29: Ангар Склад 2 въезд
A30: Задний ход, въезд на территорию | B30: Самосвал красный | C30: щебень | D30: 1 | F30: E33149364_6_20251114T125702Z.jpg | G30: Ангар Склад 2 въезд
A31: Въезд на второстепенную дорогу | B31: Трактор базы | C31: шина | D31: 1 | F31: E33149364_6_20251114T125754Z.jpg | G31: Ангар Склад 2 въезд
A32: Выезд с территории | B32: Самосвал красный | C32: порожний | F32: E33149364_6_20251114T130033Z.jpg | G32: Ангар Склад 2 въезд
A33: Задний ход, въезд на территорию | B33: Самосвал красный | C33: щебень | D33: 1 | F33: E33149364_6_20251114T131318Z.jpg | G33: Ангар Склад 2 въезд
A34: Выезд с территории | B34: Самосвал красный | C34: порожний | F34: E33149364_6_20251114T131619Z.jpg | G34: Ангар Склад 2 въезд
A35: Задний ход, въезд на территорию | B35: Самосвал красный | C35: щебень | D35: 1 | F35: E33149364_6_20251114T132811Z.jpg | G35: Ангар Склад 2 въезд
A36: Выезд с территории | B36: Самосвал красный | C36: порожний | F36: E33149364_6_20251114T133038Z.jpg | G36: Ангар Склад 2 въезд
A37: Задний ход, въезд на территорию | B37: Самосвал красный | C37: щебень | D37: 1 | F37: E33149364_6_20251114T134227Z.jpg | G37: Ангар Склад 2 въезд
A38: Выезд с территории | B38: Самосвал красный | C38: порожний | F38: E33149364_6_20251114T134639Z.jpg | G38: Ангар Склад 2 въезд
A39: Въезд на базу | B39: Погрузчик базы | C39: порожний | F39: E33149364_6_20251114T142453Z.jpg | G39: Ангар Склад 2 въезд
A40: Фиксация в кадре | B40: Территория | F40: E33149364_7_20251110T092437Z.jpg | G40: Пилорама поката
A41: Доставка | B41: Трактор базы | C41: бревна | D41: 2 | F41: E33149364_7_20251110T092515Z.jpg | G41: Пилорама поката
A42: Доставка | B42: Трактор базы | C42: бревна | D42: 1 | F42: E33149364_7_20251110T100243Z.jpg | G42: Пилорама поката
A43: Доставка | B43: Трактор базы | C43: бревна | D43: 2 | F43: E33149364_7_20251110T103012Z.jpg | G43: Пилорама поката
A44: Доставка | B44: Трактор базы | C44: бревна | D44: 2 | F44: E33149364_7_20251110T103559Z.jpg | G44: Пилорама поката
A45: Доставка | B45: Трактор базы | C45: бревна | D45: 1 | F45: E33149364_7_20251110T104132Z.jpg | G45: Пилорама поката
A46: Доставка | B46: Трактор базы | C46: бревна | D46: 2 | F46: E33149364_7_20251110T105030Z.jpg | G46: Пилорама поката
...

Sheet 4 Крыльцо офиса
A1: День нед | B1: Дата | C1: Время | D1: Событие | E1: Объект | F1: Груз | G1: Кол-во | H1: Примечание | I1: Name | J1: Folder Path | K1: RelativePath | L1: Подпись | M1: Ссылка на фото
A2: пн | B2: 45971 | C2: 0.34798611 | D2: Фиксация в кадре | E2: Территория | H2: Начало дня | I2: K07156189_21_20251110T082106Z.jpg | J2: C:\ВИДЕОНАБЛЮДЕНИЕ\4 Крыльцо офиса\ | K2: 4 Крыльцо офиса\K07156189_21_20251110T082106Z.jpg | L2: пн 10.11.2025 — 08:21:06 | M2: =HYPERLINK(склад2въезд13[[#This Row],[RelativePath]]) -> 4 Крыльцо офиса\K07156189_21_20251110T082106Z.jpg
A3: пн | B3: 45971 | C3: 0.74396991 | D3: Фиксация в кадре | E3: Территория | H3: Конец дня | I3: K07156189_21_20251110T175119Z.jpg | J3: C:\ВИДЕОНАБЛЮДЕНИЕ\4 Крыльцо офиса\ | K3: 4 Крыльцо офиса\K07156189_21_20251110T175119Z.jpg | L3: пн 10.11.2025 — 17:51:19 | M3: =HYPERLINK(склад2въезд13[[#This Row],[RelativePath]]) -> 4 Крыльцо офиса\K07156189_21_20251110T175119Z.jpg
A4: вт | B4: 45972 | C4: 0.34685185 | D4: Фиксация в кадре | E4: Территория | H4: Начало дня | I4: K07156189_21_20251111T081928Z.jpg | J4: C:\ВИДЕОНАБЛЮДЕНИЕ\4 Крыльцо офиса\ | K4: 4 Крыльцо офиса\K07156189_21_20251111T081928Z.jpg | L4: вт 11.11.2025 — 08:19:28 | M4: =HYPERLINK(склад2въезд13[[#This Row],[RelativePath]]) -> 4 Крыльцо офиса\K07156189_21_20251111T081928Z.jpg
A5: вт | B5: 45972 | C5: 0.69240741 | D5: Фиксация в кадре | E5: Территория | H5: Конец дня | I5: K07156189_21_20251111T163704Z.jpg | J5: C:\ВИДЕОНАБЛЮДЕНИЕ\4 Крыльцо офиса\ | K5: 4 Крыльцо офиса\K07156189_21_20251111T163704Z.jpg | L5: вт 11.11.2025 — 16:37:04 | M5: =HYPERLINK(склад2въезд13[[#This Row],[RelativePath]]) -> 4 Крыльцо офиса\K07156189_21_20251111T163704Z.jpg
A6: ср | B6: 45973 | C6: 0.51393519 | D6: Фиксация в кадре | E6: Территория | H6: Трактор сгребает землю | I6: K07156189_21_20251112T122004Z.jpg | J6: C:\ВИДЕОНАБЛЮДЕНИЕ\4 Крыльцо офиса\ | K6: 4 Крыльцо офиса\K07156189_21_20251112T122004Z.jpg | L6: ср 12.11.2025 — 12:20:04 | M6: =HYPERLINK(склад2въезд13[[#This Row],[RelativePath]]) -> 4 Крыльцо офиса\K07156189_21_20251112T122004Z.jpg
A7: ср | B7: 45973 | C7: 0.55550926 | D7: Фиксация в кадре | E7: Территория | H7: Трактор сгребает землю | I7: K07156189_21_20251112T131956Z.jpg | J7: C:\ВИДЕОНАБЛЮДЕНИЕ\4 Крыльцо офиса\ | K7: 4 Крыльцо офиса\K07156189_21_20251112T131956Z.jpg | L7: ср 12.11.2025 — 13:19:56 | M7: =HYPERLINK(склад2въезд13[[#This Row],[RelativePath]]) -> 4 Крыльцо офиса\K07156189_21_20251112T131956Z.jpg
A8: ср | B8: 45973 | C8: 0.69413194 | D8: Фиксация в кадре | E8: Территория | H8: Загрузка земли в самосвал | I8: K07156189_21_20251112T163933Z.jpg | J8: C:\ВИДЕОНАБЛЮДЕНИЕ\4 Крыльцо офиса\ | K8: 4 Крыльцо офиса\K07156189_21_20251112T163933Z.jpg | L8: ср 12.11.2025 — 16:39:33 | M8: =HYPERLINK(склад2въезд13[[#This Row],[RelativePath]]) -> 4 Крыльцо офиса\K07156189_21_20251112T163933Z.jpg
A9: ср | B9: 45973 | C9: 0.73761574 | D9: Фиксация в кадре | E9: Территория | H9: Конец дня | I9: K07156189_21_20251112T174210Z.jpg | J9: C:\ВИДЕОНАБЛЮДЕНИЕ\4 Крыльцо офиса\ | K9: 4 Крыльцо офиса\K07156189_21_20251112T174210Z.jpg | L9: ср 12.11.2025 — 17:42:10 | M9: =HYPERLINK(склад2въезд13[[#This Row],[RelativePath]]) -> 4 Крыльцо офиса\K07156189_21_20251112T174210Z.jpg
A10: чт | B10: 45974 | C10: 0.34179398 | D10: Фиксация в кадре | E10: Территория | H10: Начало дня | I10: K07156189_21_20251113T081211Z.jpg | J10: C:\ВИДЕОНАБЛЮДЕНИЕ\4 Крыльцо офиса\ | K10: 4 Крыльцо офиса\K07156189_21_20251113T081211Z.jpg | L10: чт 13.11.2025 — 08:12:11 | M10: =HYPERLINK(склад2въезд13[[#This Row],[RelativePath]]) -> 4 Крыльцо офиса\K07156189_21_20251113T081211Z.jpg
A11: чт | B11: 45974 | C11: 0.40744213 | D11: Фиксация в кадре | E11: Территория | H11: Трактор сгребает землю | I11: K07156189_21_20251113T094643Z.jpg | J11: C:\ВИДЕОНАБЛЮДЕНИЕ\4 Крыльцо офиса\ | K11: 4 Крыльцо офиса\K07156189_21_20251113T094643Z.jpg | L11: чт 13.11.2025 — 09:46:43 | M11: =HYPERLINK(склад2въезд13[[#This Row],[RelativePath]]) -> 4 Крыльцо офиса\K07156189_21_20251113T094643Z.jpg
A12: чт | B12: 45974 | C12: 0.741875 | D12: Фиксация в кадре | E12: Территория | H12: Конец дня | I12: K07156189_21_20251113T174818Z.jpg | J12: C:\ВИДЕОНАБЛЮДЕНИЕ\4 Крыльцо офиса\ | K12: 4 Крыльцо офиса\K07156189_21_20251113T174818Z.jpg | L12: чт 13.11.2025 — 17:48:18 | M12: =HYPERLINK(склад2въезд13[[#This Row],[RelativePath]]) -> 4 Крыльцо офиса\K07156189_21_20251113T174818Z.jpg
A13: пт | B13: 45975 | C13: 0.39813657 | D13: Фиксация в кадре | E13: Территория | H13: Начало дня | I13: K07156189_21_20251114T093319Z.jpg | J13: C:\ВИДЕОНАБЛЮДЕНИЕ\4 Крыльцо офиса\ | K13: 4 Крыльцо офиса\K07156189_21_20251114T093319Z.jpg | L13: пт 14.11.2025 — 09:33:19 | M13: =HYPERLINK(склад2въезд13[[#This Row],[RelativePath]]) -> 4 Крыльцо офиса\K07156189_21_20251114T093319Z.jpg
